<?xml version="1.0" encoding="UTF-8"?>
<!-- Generated by org.testng.reporters.JUnitXMLReporter -->
<testsuite hostname="ylheq" ignored="0" name="这些是测试模块" tests="3" failures="2" timestamp="19 十二月 2019 10:07:09 GMT" time="0.072" errors="0">
  <testcase name="test1" time="0.018" classname="com.test.testng.Demo1"/>
  <testcase name="test2" time="0.003" classname="com.test.testng.Demo1">
    <failure type="java.lang.AssertionError" message="expected [2] but found [1]">
      <![CDATA[java.lang.AssertionError: expected [2] but found [1]
	at com.test.testng.Demo1.test2(Demo1.java:16)
... Removed 31 stack frames]]>
    </failure>
  </testcase> <!-- test2 -->
  <testcase name="test3" time="0.002" classname="com.test.testng.Demo1">
    <failure type="java.lang.RuntimeException" message="这是我们自己的运行时异常">
      <![CDATA[java.lang.RuntimeException: 这是我们自己的运行时异常
	at com.test.testng.Demo1.test3(Demo1.java:22)
... Removed 25 stack frames]]>
    </failure>
  </testcase> <!-- test3 -->
</testsuite> <!-- 这些是测试模块 -->
